[2025-07-05 00:05:46 +0000] [2590187] [INFO] Starting gunicorn 23.0.0
[2025-07-05 00:05:48 +0000] [2590187] [ERROR] Connection in use: ('127.0.0.1', 5000)
[2025-07-05 00:05:48 +0000] [2590187] [ERROR] connection to ('127.0.0.1', 5000) failed: [Errno 98] Address already in use
[2025-07-05 00:05:49 +0000] [2590187] [ERROR] Connection in use: ('127.0.0.1', 5000)
[2025-07-05 00:05:49 +0000] [2590187] [ERROR] connection to ('127.0.0.1', 5000) failed: [Errno 98] Address already in use
[2025-07-05 00:05:50 +0000] [2590187] [ERROR] Connection in use: ('127.0.0.1', 5000)
[2025-07-05 00:05:50 +0000] [2590187] [ERROR] connection to ('127.0.0.1', 5000) failed: [Errno 98] Address already in use
[2025-07-05 00:05:51 +0000] [2590187] [ERROR] Connection in use: ('127.0.0.1', 5000)
[2025-07-05 00:05:51 +0000] [2590187] [ERROR] connection to ('127.0.0.1', 5000) failed: [Errno 98] Address already in use
[2025-07-05 00:05:52 +0000] [2590187] [ERROR] Connection in use: ('127.0.0.1', 5000)
[2025-07-05 00:05:52 +0000] [2590187] [ERROR] connection to ('127.0.0.1', 5000) failed: [Errno 98] Address already in use
[2025-07-05 00:05:53 +0000] [2590187] [ERROR] Can't connect to ('127.0.0.1', 5000)
[2025-07-05 00:08:02 +0000] [2591078] [INFO] Starting gunicorn 23.0.0
[2025-07-05 00:08:02 +0000] [2591078] [ERROR] Connection in use: ('127.0.0.1', 5000)
[2025-07-05 00:08:02 +0000] [2591078] [ERROR] connection to ('127.0.0.1', 5000) failed: [Errno 98] Address already in use
[2025-07-05 00:08:03 +0000] [2591078] [ERROR] Connection in use: ('127.0.0.1', 5000)
[2025-07-05 00:08:03 +0000] [2591078] [ERROR] connection to ('127.0.0.1', 5000) failed: [Errno 98] Address already in use
[2025-07-05 00:08:05 +0000] [2591078] [ERROR] Connection in use: ('127.0.0.1', 5000)
[2025-07-05 00:08:05 +0000] [2591078] [ERROR] connection to ('127.0.0.1', 5000) failed: [Errno 98] Address already in use
[2025-07-05 00:08:06 +0000] [2591078] [ERROR] Connection in use: ('127.0.0.1', 5000)
[2025-07-05 00:08:06 +0000] [2591078] [ERROR] connection to ('127.0.0.1', 5000) failed: [Errno 98] Address already in use
[2025-07-05 00:08:07 +0000] [2591078] [ERROR] Connection in use: ('127.0.0.1', 5000)
[2025-07-05 00:08:07 +0000] [2591078] [ERROR] connection to ('127.0.0.1', 5000) failed: [Errno 98] Address already in use
[2025-07-05 00:08:08 +0000] [2591078] [ERROR] Can't connect to ('127.0.0.1', 5000)
[2025-07-05 00:53:07 +0000] [2607260] [INFO] Starting gunicorn 23.0.0
[2025-07-05 00:53:07 +0000] [2607260] [INFO] Listening at: http://127.0.0.1:5000 (2607260)
[2025-07-05 00:53:07 +0000] [2607260] [INFO] Using worker: sync
[2025-07-05 00:53:07 +0000] [2607273] [INFO] Booting worker with pid: 2607273
[2025-07-05 00:53:07 +0000] [2607273] [ERROR] Exception in worker process
Traceback (most recent call last):
  File "/usr/local/lib/python3.10/dist-packages/gunicorn/arbiter.py", line 608, in spawn_worker
    worker.init_process()
  File "/usr/local/lib/python3.10/dist-packages/gunicorn/workers/base.py", line 135, in init_process
    self.load_wsgi()
  File "/usr/local/lib/python3.10/dist-packages/gunicorn/workers/base.py", line 147, in load_wsgi
    self.wsgi = self.app.wsgi()
  File "/usr/local/lib/python3.10/dist-packages/gunicorn/app/base.py", line 66, in wsgi
    self.callable = self.load()
  File "/usr/local/lib/python3.10/dist-packages/gunicorn/app/wsgiapp.py", line 57, in load
    return self.load_wsgiapp()
  File "/usr/local/lib/python3.10/dist-packages/gunicorn/app/wsgiapp.py", line 47, in load_wsgiapp
    return util.import_app(self.app_uri)
  File "/usr/local/lib/python3.10/dist-packages/gunicorn/util.py", line 370, in import_app
    mod = importlib.import_module(module)
  File "/usr/lib/python3.10/importlib/__init__.py", line 126, in import_module
    return _bootstrap._gcd_import(name[level:], package, level)
  File "<frozen importlib._bootstrap>", line 1050, in _gcd_import
  File "<frozen importlib._bootstrap>", line 1027, in _find_and_load
  File "<frozen importlib._bootstrap>", line 1004, in _find_and_load_unlocked
ModuleNotFoundError: No module named 'server'
[2025-07-05 00:53:07 +0000] [2607273] [INFO] Worker exiting (pid: 2607273)
[2025-07-05 00:53:07 +0000] [2607274] [INFO] Booting worker with pid: 2607274
[2025-07-05 00:53:07 +0000] [2607274] [ERROR] Exception in worker process
Traceback (most recent call last):
  File "/usr/local/lib/python3.10/dist-packages/gunicorn/arbiter.py", line 608, in spawn_worker
    worker.init_process()
  File "/usr/local/lib/python3.10/dist-packages/gunicorn/workers/base.py", line 135, in init_process
    self.load_wsgi()
  File "/usr/local/lib/python3.10/dist-packages/gunicorn/workers/base.py", line 147, in load_wsgi
    self.wsgi = self.app.wsgi()
  File "/usr/local/lib/python3.10/dist-packages/gunicorn/app/base.py", line 66, in wsgi
    self.callable = self.load()
  File "/usr/local/lib/python3.10/dist-packages/gunicorn/app/wsgiapp.py", line 57, in load
    return self.load_wsgiapp()
  File "/usr/local/lib/python3.10/dist-packages/gunicorn/app/wsgiapp.py", line 47, in load_wsgiapp
    return util.import_app(self.app_uri)
  File "/usr/local/lib/python3.10/dist-packages/gunicorn/util.py", line 370, in import_app
    mod = importlib.import_module(module)
  File "/usr/lib/python3.10/importlib/__init__.py", line 126, in import_module
    return _bootstrap._gcd_import(name[level:], package, level)
  File "<frozen importlib._bootstrap>", line 1050, in _gcd_import
  File "<frozen importlib._bootstrap>", line 1027, in _find_and_load
  File "<frozen importlib._bootstrap>", line 1004, in _find_and_load_unlocked
ModuleNotFoundError: No module named 'server'
[2025-07-05 00:53:07 +0000] [2607274] [INFO] Worker exiting (pid: 2607274)
[2025-07-05 00:53:07 +0000] [2607260] [ERROR] Worker (pid:2607273) exited with code 3
[2025-07-05 00:53:07 +0000] [2607276] [INFO] Booting worker with pid: 2607276
[2025-07-05 00:53:07 +0000] [2607260] [ERROR] Worker (pid:2607274) was sent SIGTERM!
[2025-07-05 00:53:07 +0000] [2607276] [ERROR] Exception in worker process
Traceback (most recent call last):
  File "/usr/local/lib/python3.10/dist-packages/gunicorn/arbiter.py", line 608, in spawn_worker
    worker.init_process()
  File "/usr/local/lib/python3.10/dist-packages/gunicorn/workers/base.py", line 135, in init_process
    self.load_wsgi()
  File "/usr/local/lib/python3.10/dist-packages/gunicorn/workers/base.py", line 147, in load_wsgi
    self.wsgi = self.app.wsgi()
  File "/usr/local/lib/python3.10/dist-packages/gunicorn/app/base.py", line 66, in wsgi
    self.callable = self.load()
  File "/usr/local/lib/python3.10/dist-packages/gunicorn/app/wsgiapp.py", line 57, in load
    return self.load_wsgiapp()
  File "/usr/local/lib/python3.10/dist-packages/gunicorn/app/wsgiapp.py", line 47, in load_wsgiapp
    return util.import_app(self.app_uri)
  File "/usr/local/lib/python3.10/dist-packages/gunicorn/util.py", line 370, in import_app
    mod = importlib.import_module(module)
  File "/usr/lib/python3.10/importlib/__init__.py", line 126, in import_module
    return _bootstrap._gcd_import(name[level:], package, level)
  File "<frozen importlib._bootstrap>", line 1050, in _gcd_import
  File "<frozen importlib._bootstrap>", line 1027, in _find_and_load
  File "<frozen importlib._bootstrap>", line 1004, in _find_and_load_unlocked
ModuleNotFoundError: No module named 'server'
[2025-07-05 00:53:07 +0000] [2607276] [INFO] Worker exiting (pid: 2607276)
[2025-07-05 00:53:07 +0000] [2607275] [INFO] Booting worker with pid: 2607275
[2025-07-05 00:53:07 +0000] [2607275] [ERROR] Exception in worker process
Traceback (most recent call last):
  File "/usr/local/lib/python3.10/dist-packages/gunicorn/arbiter.py", line 608, in spawn_worker
    worker.init_process()
  File "/usr/local/lib/python3.10/dist-packages/gunicorn/workers/base.py", line 135, in init_process
    self.load_wsgi()
  File "/usr/local/lib/python3.10/dist-packages/gunicorn/workers/base.py", line 147, in load_wsgi
    self.wsgi = self.app.wsgi()
  File "/usr/local/lib/python3.10/dist-packages/gunicorn/app/base.py", line 66, in wsgi
    self.callable = self.load()
  File "/usr/local/lib/python3.10/dist-packages/gunicorn/app/wsgiapp.py", line 57, in load
    return self.load_wsgiapp()
  File "/usr/local/lib/python3.10/dist-packages/gunicorn/app/wsgiapp.py", line 47, in load_wsgiapp
    return util.import_app(self.app_uri)
  File "/usr/local/lib/python3.10/dist-packages/gunicorn/util.py", line 370, in import_app
    mod = importlib.import_module(module)
  File "/usr/lib/python3.10/importlib/__init__.py", line 126, in import_module
    return _bootstrap._gcd_import(name[level:], package, level)
  File "<frozen importlib._bootstrap>", line 1050, in _gcd_import
  File "<frozen importlib._bootstrap>", line 1027, in _find_and_load
  File "<frozen importlib._bootstrap>", line 1004, in _find_and_load_unlocked
ModuleNotFoundError: No module named 'server'
[2025-07-05 00:53:07 +0000] [2607275] [INFO] Worker exiting (pid: 2607275)
[2025-07-05 00:53:07 +0000] [2607260] [ERROR] Worker (pid:2607275) exited with code 3
[2025-07-05 00:53:07 +0000] [2607260] [ERROR] Worker (pid:2607276) exited with code 3
Traceback (most recent call last):
  File "/usr/local/lib/python3.10/dist-packages/gunicorn/arbiter.py", line 208, in run
    self.sleep()
  File "/usr/local/lib/python3.10/dist-packages/gunicorn/arbiter.py", line 359, in sleep
    ready = select.select([self.PIPE[0]], [], [], 1.0)
  File "/usr/local/lib/python3.10/dist-packages/gunicorn/arbiter.py", line 241, in handle_chld
    self.reap_workers()
  File "/usr/local/lib/python3.10/dist-packages/gunicorn/arbiter.py", line 529, in reap_workers
    raise HaltServer(reason, self.WORKER_BOOT_ERROR)
gunicorn.errors.HaltServer: <HaltServer 'Worker failed to boot.' 3>

During handling of the above exception, another exception occurred:

Traceback (most recent call last):
  File "/usr/local/bin/gunicorn", line 8, in <module>
    sys.exit(run())
  File "/usr/local/lib/python3.10/dist-packages/gunicorn/app/wsgiapp.py", line 66, in run
    WSGIApplication("%(prog)s [OPTIONS] [APP_MODULE]", prog=prog).run()
  File "/usr/local/lib/python3.10/dist-packages/gunicorn/app/base.py", line 235, in run
    super().run()
  File "/usr/local/lib/python3.10/dist-packages/gunicorn/app/base.py", line 71, in run
    Arbiter(self).run()
  File "/usr/local/lib/python3.10/dist-packages/gunicorn/arbiter.py", line 228, in run
    self.halt(reason=inst.reason, exit_status=inst.exit_status)
  File "/usr/local/lib/python3.10/dist-packages/gunicorn/arbiter.py", line 341, in halt
    self.stop()
  File "/usr/local/lib/python3.10/dist-packages/gunicorn/arbiter.py", line 395, in stop
    time.sleep(0.1)
  File "/usr/local/lib/python3.10/dist-packages/gunicorn/arbiter.py", line 241, in handle_chld
    self.reap_workers()
  File "/usr/local/lib/python3.10/dist-packages/gunicorn/arbiter.py", line 529, in reap_workers
    raise HaltServer(reason, self.WORKER_BOOT_ERROR)
gunicorn.errors.HaltServer: <HaltServer 'Worker failed to boot.' 3>
Error in sys.excepthook:
Traceback (most recent call last):
  File "/usr/lib/python3/dist-packages/apport_python_hook.py", line 55, in apport_excepthook
    import apt_pkg
  File "/usr/local/lib/python3.10/dist-packages/gunicorn/arbiter.py", line 241, in handle_chld
    self.reap_workers()
  File "/usr/local/lib/python3.10/dist-packages/gunicorn/arbiter.py", line 529, in reap_workers
    raise HaltServer(reason, self.WORKER_BOOT_ERROR)
gunicorn.errors.HaltServer: <HaltServer 'Worker failed to boot.' 3>

Original exception was:
Traceback (most recent call last):
  File "/usr/local/lib/python3.10/dist-packages/gunicorn/arbiter.py", line 208, in run
    self.sleep()
  File "/usr/local/lib/python3.10/dist-packages/gunicorn/arbiter.py", line 359, in sleep
    ready = select.select([self.PIPE[0]], [], [], 1.0)
  File "/usr/local/lib/python3.10/dist-packages/gunicorn/arbiter.py", line 241, in handle_chld
    self.reap_workers()
  File "/usr/local/lib/python3.10/dist-packages/gunicorn/arbiter.py", line 529, in reap_workers
    raise HaltServer(reason, self.WORKER_BOOT_ERROR)
gunicorn.errors.HaltServer: <HaltServer 'Worker failed to boot.' 3>

During handling of the above exception, another exception occurred:

Traceback (most recent call last):
  File "/usr/local/bin/gunicorn", line 8, in <module>
    sys.exit(run())
  File "/usr/local/lib/python3.10/dist-packages/gunicorn/app/wsgiapp.py", line 66, in run
    WSGIApplication("%(prog)s [OPTIONS] [APP_MODULE]", prog=prog).run()
  File "/usr/local/lib/python3.10/dist-packages/gunicorn/app/base.py", line 235, in run
    super().run()
  File "/usr/local/lib/python3.10/dist-packages/gunicorn/app/base.py", line 71, in run
    Arbiter(self).run()
  File "/usr/local/lib/python3.10/dist-packages/gunicorn/arbiter.py", line 228, in run
    self.halt(reason=inst.reason, exit_status=inst.exit_status)
  File "/usr/local/lib/python3.10/dist-packages/gunicorn/arbiter.py", line 341, in halt
    self.stop()
  File "/usr/local/lib/python3.10/dist-packages/gunicorn/arbiter.py", line 395, in stop
    time.sleep(0.1)
  File "/usr/local/lib/python3.10/dist-packages/gunicorn/arbiter.py", line 241, in handle_chld
    self.reap_workers()
  File "/usr/local/lib/python3.10/dist-packages/gunicorn/arbiter.py", line 529, in reap_workers
    raise HaltServer(reason, self.WORKER_BOOT_ERROR)
gunicorn.errors.HaltServer: <HaltServer 'Worker failed to boot.' 3>
